2022-08-07 22:45:44,850 INFO    Thread-9  :1676533 [wandb_setup.py:_flush():76] Configure stats pid to 1676533
2022-08-07 22:45:44,850 INFO    Thread-9  :1676533 [wandb_setup.py:_flush():76] Loading settings from /home/kana/.config/wandb/settings
2022-08-07 22:45:44,850 INFO    Thread-9  :1676533 [wandb_setup.py:_flush():76] Loading settings from wandb/settings
2022-08-07 22:45:44,850 INFO    Thread-9  :1676533 [wandb_setup.py:_flush():76] Loading settings from environment variables: {'project': 'noisy_label_cleaning_b', 'entity': 'kka-na', 'root_dir': '/home/kana/Documents/Training/Reliable_Dataset/cleaning/script', 'run_id': 'hxrddej8', 'sweep_param_path': '/home/kana/Documents/Training/Reliable_Dataset/cleaning/script/wandb/sweep-ddys6s94/config-hxrddej8.yaml', 'sweep_id': 'ddys6s94'}
2022-08-07 22:45:44,850 WARNING Thread-9  :1676533 [wandb_setup.py:_flush():76] Could not save program above cwd: ../src/hyp_tuning.py
2022-08-07 22:45:44,851 INFO    Thread-9  :1676533 [wandb_setup.py:_flush():76] Inferring run settings from compute environment: {'program_relpath': None, 'program': '../src/hyp_tuning.py'}
2022-08-07 22:45:44,851 INFO    Thread-9  :1676533 [wandb_init.py:_log_setup():461] Logging user logs to /home/kana/Documents/Training/Reliable_Dataset/cleaning/script/wandb/run-20220807_224544-hxrddej8/logs/debug.log
2022-08-07 22:45:44,851 INFO    Thread-9  :1676533 [wandb_init.py:_log_setup():462] Logging internal logs to /home/kana/Documents/Training/Reliable_Dataset/cleaning/script/wandb/run-20220807_224544-hxrddej8/logs/debug-internal.log
2022-08-07 22:45:44,854 INFO    Thread-9  :1676533 [wandb_init.py:init():495] calling init triggers
2022-08-07 22:45:44,855 INFO    Thread-9  :1676533 [wandb_init.py:init():498] wandb.init called with sweep_config: {'BATCH_SIZE_PER_IMAGE': 64, 'IMS_PER_BATCH': 4, 'iteration': 1000, 'learning_rate': 0.0008996770335134629, 'model': 'COCO-Detection/faster_rcnn_R_101_DC5_3x.yaml'}
config: {}
2022-08-07 22:45:44,858 INFO    Thread-9  :1676533 [wandb_init.py:init():548] starting backend
2022-08-07 22:45:44,858 INFO    Thread-9  :1676533 [backend.py:_multiprocessing_setup():97] multiprocessing start_methods=fork,spawn,forkserver, using: spawn
2022-08-07 22:45:44,867 INFO    Thread-9  :1676533 [backend.py:ensure_launched():217] starting backend process...
2022-08-07 22:45:44,900 INFO    Thread-9  :1676533 [backend.py:ensure_launched():222] started backend process with pid: 1683071
2022-08-07 22:45:44,901 INFO    Thread-9  :1676533 [wandb_init.py:init():558] backend started and connected
2022-08-07 22:45:44,916 INFO    Thread-9  :1676533 [wandb_run.py:_config_callback():1131] config_cb None None {'BATCH_SIZE_PER_IMAGE': 64, 'IMS_PER_BATCH': 4, 'iteration': 1000, 'learning_rate': 0.0008996770335134629, 'model': 'COCO-Detection/faster_rcnn_R_101_DC5_3x.yaml'}
2022-08-07 22:45:44,920 INFO    Thread-9  :1676533 [wandb_init.py:init():634] updated telemetry
2022-08-07 22:45:44,922 INFO    Thread-9  :1676533 [wandb_init.py:init():665] communicating run to backend with 30 second timeout
2022-08-07 22:45:45,730 INFO    Thread-9  :1676533 [wandb_run.py:_on_init():1919] communicating current version
2022-08-07 22:45:45,770 INFO    Thread-9  :1676533 [wandb_run.py:_on_init():1923] got version response upgrade_message: "wandb version 0.13.1 is available!  To upgrade, please run:\n $ pip install wandb --upgrade"

2022-08-07 22:45:45,770 INFO    Thread-9  :1676533 [wandb_init.py:init():700] starting run threads in backend
2022-08-07 22:45:46,923 INFO    Thread-9  :1676533 [wandb_run.py:_console_start():1893] atexit reg
2022-08-07 22:45:46,926 INFO    Thread-9  :1676533 [wandb_run.py:_redirect():1766] redirect: SettingsConsole.REDIRECT
2022-08-07 22:45:46,927 INFO    Thread-9  :1676533 [wandb_run.py:_redirect():1771] Redirecting console.
2022-08-07 22:45:46,927 ERROR   Thread-9  :1676533 [wandb_run.py:_redirect():1830] Failed to redirect.
Traceback (most recent call last):
  File "/home/kana/yes/envs/detectron2/lib/python3.8/site-packages/wandb/sdk/wandb_run.py", line 1823, in _redirect
    out_redir.install()
  File "/home/kana/yes/envs/detectron2/lib/python3.8/site-packages/wandb/sdk/lib/redirect.py", line 702, in install
    _WSCH.add_fd(self._pipe_read_fd)
  File "/home/kana/yes/envs/detectron2/lib/python3.8/site-packages/wandb/sdk/lib/redirect.py", line 652, in add_fd
    self._register()
  File "/home/kana/yes/envs/detectron2/lib/python3.8/site-packages/wandb/sdk/lib/redirect.py", line 637, in _register
    old_handler = signal.signal(signal.SIGWINCH, lambda *_: None)
  File "/home/kana/yes/envs/detectron2/lib/python3.8/signal.py", line 47, in signal
    handler = _signal.signal(_enum_to_int(signalnum), _enum_to_int(handler))
ValueError: signal only works in main thread
2022-08-07 22:45:46,928 INFO    Thread-9  :1676533 [wandb_init.py:init():732] run started, returning control to user process
2022-08-07 22:56:53,968 ERROR   Thread-2  :1676533 [retry.py:__call__():132] Retry attempt failed:
Traceback (most recent call last):
  File "/home/kana/yes/envs/detectron2/lib/python3.8/site-packages/urllib3/connection.py", line 174, in _new_conn
    conn = connection.create_connection(
  File "/home/kana/yes/envs/detectron2/lib/python3.8/site-packages/urllib3/util/connection.py", line 95, in create_connection
    raise err
  File "/home/kana/yes/envs/detectron2/lib/python3.8/site-packages/urllib3/util/connection.py", line 85, in create_connection
    sock.connect(sa)
OSError: [Errno 101] Network is unreachable

During handling of the above exception, another exception occurred:

Traceback (most recent call last):
  File "/home/kana/yes/envs/detectron2/lib/python3.8/site-packages/urllib3/connectionpool.py", line 703, in urlopen
    httplib_response = self._make_request(
  File "/home/kana/yes/envs/detectron2/lib/python3.8/site-packages/urllib3/connectionpool.py", line 386, in _make_request
    self._validate_conn(conn)
  File "/home/kana/yes/envs/detectron2/lib/python3.8/site-packages/urllib3/connectionpool.py", line 1042, in _validate_conn
    conn.connect()
  File "/home/kana/yes/envs/detectron2/lib/python3.8/site-packages/urllib3/connection.py", line 358, in connect
    self.sock = conn = self._new_conn()
  File "/home/kana/yes/envs/detectron2/lib/python3.8/site-packages/urllib3/connection.py", line 186, in _new_conn
    raise NewConnectionError(
urllib3.exceptions.NewConnectionError: <urllib3.connection.HTTPSConnection object at 0x7f0f8b788640>: Failed to establish a new connection: [Errno 101] Network is unreachable

During handling of the above exception, another exception occurred:

Traceback (most recent call last):
  File "/home/kana/yes/envs/detectron2/lib/python3.8/site-packages/requests/adapters.py", line 489, in send
    resp = conn.urlopen(
  File "/home/kana/yes/envs/detectron2/lib/python3.8/site-packages/urllib3/connectionpool.py", line 787, in urlopen
    retries = retries.increment(
  File "/home/kana/yes/envs/detectron2/lib/python3.8/site-packages/urllib3/util/retry.py", line 592, in increment
    raise MaxRetryError(_pool, url, error or ResponseError(cause))
urllib3.exceptions.MaxRetryError: HTTPSConnectionPool(host='api.wandb.ai', port=443): Max retries exceeded with url: /graphql (Caused by NewConnectionError('<urllib3.connection.HTTPSConnection object at 0x7f0f8b788640>: Failed to establish a new connection: [Errno 101] Network is unreachable'))

During handling of the above exception, another exception occurred:

Traceback (most recent call last):
  File "/home/kana/yes/envs/detectron2/lib/python3.8/site-packages/wandb/sdk/lib/retry.py", line 108, in __call__
    result = self._call_fn(*args, **kwargs)
  File "/home/kana/yes/envs/detectron2/lib/python3.8/site-packages/wandb/sdk/internal/internal_api.py", line 158, in execute
    return self.client.execute(*args, **kwargs)
  File "/home/kana/yes/envs/detectron2/lib/python3.8/site-packages/wandb/vendor/gql-0.2.0/wandb_gql/client.py", line 52, in execute
    result = self._get_result(document, *args, **kwargs)
  File "/home/kana/yes/envs/detectron2/lib/python3.8/site-packages/wandb/vendor/gql-0.2.0/wandb_gql/client.py", line 60, in _get_result
    return self.transport.execute(document, *args, **kwargs)
  File "/home/kana/yes/envs/detectron2/lib/python3.8/site-packages/wandb/vendor/gql-0.2.0/wandb_gql/transport/requests.py", line 38, in execute
    request = requests.post(self.url, **post_args)
  File "/home/kana/yes/envs/detectron2/lib/python3.8/site-packages/requests/api.py", line 115, in post
    return request("post", url, data=data, json=json, **kwargs)
  File "/home/kana/yes/envs/detectron2/lib/python3.8/site-packages/requests/api.py", line 59, in request
    return session.request(method=method, url=url, **kwargs)
  File "/home/kana/yes/envs/detectron2/lib/python3.8/site-packages/requests/sessions.py", line 587, in request
    resp = self.send(prep, **send_kwargs)
  File "/home/kana/yes/envs/detectron2/lib/python3.8/site-packages/requests/sessions.py", line 701, in send
    r = adapter.send(request, **kwargs)
  File "/home/kana/yes/envs/detectron2/lib/python3.8/site-packages/requests/adapters.py", line 565, in send
    raise ConnectionError(e, request=request)
requests.exceptions.ConnectionError: HTTPSConnectionPool(host='api.wandb.ai', port=443): Max retries exceeded with url: /graphql (Caused by NewConnectionError('<urllib3.connection.HTTPSConnection object at 0x7f0f8b788640>: Failed to establish a new connection: [Errno 101] Network is unreachable'))
2022-08-07 23:16:37,029 INFO    Thread-9  :1676533 [wandb_run.py:_finish():1680] finishing run kka-na/noisy_label_cleaning_b/hxrddej8
2022-08-07 23:16:37,029 INFO    Thread-9  :1676533 [wandb_run.py:_atexit_cleanup():1862] got exitcode: 0
2022-08-07 23:16:37,033 INFO    Thread-9  :1676533 [wandb_run.py:_restore():1834] restore
2022-08-07 23:16:37,039 INFO    Thread-9  :1676533 [wandb_run.py:_on_finish():1991] got exit ret: file_counts {
  wandb_count: 1
}
pusher_stats {
  uploaded_bytes: 527
  total_bytes: 527
}

2022-08-07 23:16:37,237 INFO    Thread-9  :1676533 [wandb_run.py:_on_finish():1991] got exit ret: file_counts {
  wandb_count: 1
}
pusher_stats {
  uploaded_bytes: 527
  total_bytes: 527
}

2022-08-07 23:16:37,490 INFO    Thread-9  :1676533 [wandb_run.py:_on_finish():1991] got exit ret: file_counts {
  wandb_count: 1
}
pusher_stats {
  uploaded_bytes: 527
  total_bytes: 527
}

2022-08-07 23:16:37,670 INFO    Thread-9  :1676533 [wandb_run.py:_on_finish():1991] got exit ret: file_counts {
  wandb_count: 5
}
pusher_stats {
  uploaded_bytes: 527
  total_bytes: 6044
}

2022-08-07 23:16:37,773 INFO    Thread-9  :1676533 [wandb_run.py:_on_finish():1991] got exit ret: file_counts {
  wandb_count: 5
}
pusher_stats {
  uploaded_bytes: 527
  total_bytes: 6044
}

2022-08-07 23:16:37,875 INFO    Thread-9  :1676533 [wandb_run.py:_on_finish():1991] got exit ret: file_counts {
  wandb_count: 5
}
pusher_stats {
  uploaded_bytes: 527
  total_bytes: 6044
}

2022-08-07 23:16:37,978 INFO    Thread-9  :1676533 [wandb_run.py:_on_finish():1991] got exit ret: file_counts {
  wandb_count: 5
}
pusher_stats {
  uploaded_bytes: 527
  total_bytes: 6044
}

2022-08-07 23:16:38,081 INFO    Thread-9  :1676533 [wandb_run.py:_on_finish():1991] got exit ret: file_counts {
  wandb_count: 5
}
pusher_stats {
  uploaded_bytes: 527
  total_bytes: 6044
}

2022-08-07 23:16:38,183 INFO    Thread-9  :1676533 [wandb_run.py:_on_finish():1991] got exit ret: file_counts {
  wandb_count: 5
}
pusher_stats {
  uploaded_bytes: 6044
  total_bytes: 6044
}

2022-08-07 23:16:38,286 INFO    Thread-9  :1676533 [wandb_run.py:_on_finish():1991] got exit ret: file_counts {
  wandb_count: 5
}
pusher_stats {
  uploaded_bytes: 6044
  total_bytes: 6044
}

2022-08-07 23:16:38,388 INFO    Thread-9  :1676533 [wandb_run.py:_on_finish():1991] got exit ret: file_counts {
  wandb_count: 5
}
pusher_stats {
  uploaded_bytes: 6044
  total_bytes: 6044
}

2022-08-07 23:16:38,491 INFO    Thread-9  :1676533 [wandb_run.py:_on_finish():1991] got exit ret: file_counts {
  wandb_count: 5
}
pusher_stats {
  uploaded_bytes: 6044
  total_bytes: 6044
}

2022-08-07 23:16:38,593 INFO    Thread-9  :1676533 [wandb_run.py:_on_finish():1991] got exit ret: file_counts {
  wandb_count: 5
}
pusher_stats {
  uploaded_bytes: 6044
  total_bytes: 6044
}

2022-08-07 23:16:38,696 INFO    Thread-9  :1676533 [wandb_run.py:_on_finish():1991] got exit ret: file_counts {
  wandb_count: 5
}
pusher_stats {
  uploaded_bytes: 6044
  total_bytes: 6044
}

2022-08-07 23:16:39,367 INFO    Thread-9  :1676533 [wandb_run.py:_on_finish():1991] got exit ret: file_counts {
  wandb_count: 5
}
pusher_stats {
  uploaded_bytes: 6044
  total_bytes: 6044
}

2022-08-07 23:16:39,905 INFO    Thread-9  :1676533 [wandb_run.py:_on_finish():1991] got exit ret: done: true
exit_result {
}
file_counts {
  wandb_count: 5
}
pusher_stats {
  uploaded_bytes: 6044
  total_bytes: 6044
}
local_info {
}

2022-08-07 23:16:41,029 INFO    Thread-9  :1676533 [wandb_run.py:_footer_history_summary_info():3099] rendering history
2022-08-07 23:16:41,029 INFO    Thread-9  :1676533 [wandb_run.py:_footer_history_summary_info():3131] rendering summary
2022-08-07 23:16:41,034 INFO    Thread-9  :1676533 [wandb_run.py:_footer_sync_info():3055] logging synced files
