Process SpawnProcess-2:
Traceback (most recent call last):
  File "/home/kana/yes/envs/detectron2/lib/python3.8/site-packages/detectron2/data/catalog.py", line 51, in get
    f = self[name]
  File "/home/kana/yes/envs/detectron2/lib/python3.8/collections/__init__.py", line 1010, in __getitem__
    raise KeyError(key)
KeyError: 'iter2_a_train'
The above exception was the direct cause of the following exception:
Traceback (most recent call last):
  File "/home/kana/yes/envs/detectron2/lib/python3.8/site-packages/torch/multiprocessing/spawn.py", line 59, in _wrap
    fn(i, *args)
  File "/home/kana/yes/envs/detectron2/lib/python3.8/site-packages/detectron2/engine/launch.py", line 126, in _distributed_worker
    main_func(*args)
  File "/home/kana/Documents/Training/Reliable_Dataset/cleaning/src/train_net.py", line 129, in main
    trainer = Trainer(cfg)
  File "/home/kana/yes/envs/detectron2/lib/python3.8/site-packages/detectron2/engine/defaults.py", line 378, in __init__
    data_loader = self.build_train_loader(cfg)
  File "/home/kana/yes/envs/detectron2/lib/python3.8/site-packages/detectron2/engine/defaults.py", line 538, in build_train_loader
    return build_detection_train_loader(cfg)
  File "/home/kana/yes/envs/detectron2/lib/python3.8/site-packages/detectron2/config/config.py", line 207, in wrapped
    explicit_args = _get_args_from_config(from_config, *args, **kwargs)
  File "/home/kana/yes/envs/detectron2/lib/python3.8/site-packages/detectron2/config/config.py", line 245, in _get_args_from_config
    ret = from_config_func(*args, **kwargs)
  File "/home/kana/yes/envs/detectron2/lib/python3.8/site-packages/detectron2/data/build.py", line 337, in _train_loader_from_config
    dataset = get_detection_dataset_dicts(
  File "/home/kana/yes/envs/detectron2/lib/python3.8/site-packages/detectron2/data/build.py", line 240, in get_detection_dataset_dicts
    dataset_dicts = [DatasetCatalog.get(dataset_name) for dataset_name in names]
  File "/home/kana/yes/envs/detectron2/lib/python3.8/site-packages/detectron2/data/build.py", line 240, in <listcomp>
    dataset_dicts = [DatasetCatalog.get(dataset_name) for dataset_name in names]
  File "/home/kana/yes/envs/detectron2/lib/python3.8/site-packages/detectron2/data/catalog.py", line 53, in get
    raise KeyError(
KeyError: "Dataset 'iter2_a_train' is not registered! Available datasets are: coco_2014_train, coco_2014_val, coco_2014_minival, coco_2014_minival_100, coco_2014_valminusminival, coco_2017_train, coco_2017_val, coco_2017_test, coco_2017_test-dev, coco_2017_val_100, keypoints_coco_2014_train, keypoints_coco_2014_val, keypoints_coco_2014_minival, keypoints_coco_2014_valminusminival, keypoints_coco_2014_minival_100, keypoints_coco_2017_train, keypoints_coco_2017_val, keypoints_coco_2017_val_100, coco_2017_train_panoptic_separated, coco_2017_train_panoptic_stuffonly, coco_2017_train_panoptic, coco_2017_val_panoptic_separated, coco_2017_val_panoptic_stuffonly, coco_2017_val_panoptic, coco_2017_val_100_panoptic_separated, coco_2017_val_100_panoptic_stuffonly, coco_2017_val_100_panoptic, lvis_v1_train, lvis_v1_val, lvis_v1_test_dev, lvis_v1_test_challenge, lvis_v0.5_train, lvis_v0.5_val, lvis_v0.5_val_rand_100, lvis_v0.5_test, lvis_v0.5_train_cocofied, lvis_v0.5_val_cocofied, cityscapes_fine_instance_seg_train, cityscapes_fine_sem_seg_train, cityscapes_fine_instance_seg_val, cityscapes_fine_sem_seg_val, cityscapes_fine_instance_seg_test, cityscapes_fine_sem_seg_test, cityscapes_fine_panoptic_train, cityscapes_fine_panoptic_val, voc_2007_trainval, voc_2007_train, voc_2007_val, voc_2007_test, voc_2012_trainval, voc_2012_train, voc_2012_val, ade20k_sem_seg_train, ade20k_sem_seg_val, iter1_a_train, iter1_a_val"
During handling of the above exception, another exception occurred:
Traceback (most recent call last):
  File "/home/kana/yes/envs/detectron2/lib/python3.8/multiprocessing/process.py", line 315, in _bootstrap
    self.run()
  File "/home/kana/yes/envs/detectron2/lib/python3.8/multiprocessing/process.py", line 108, in run
    self._target(*self._args, **self._kwargs)
  File "/home/kana/yes/envs/detectron2/lib/python3.8/site-packages/torch/multiprocessing/spawn.py", line 66, in _wrap
    sys.exit(1)
  File "/home/kana/yes/envs/detectron2/lib/python3.8/site-packages/wandb/sdk/lib/exit_hooks.py", line 38, in exit
    self._orig_exit(orig_code)
SystemExit: 1
During handling of the above exception, another exception occurred:
Traceback (most recent call last):
  File "/home/kana/yes/envs/detectron2/lib/python3.8/multiprocessing/process.py", line 318, in _bootstrap
    util._exit_function()
  File "/home/kana/yes/envs/detectron2/lib/python3.8/multiprocessing/util.py", line 357, in _exit_function
    p.join()
  File "/home/kana/yes/envs/detectron2/lib/python3.8/multiprocessing/process.py", line 149, in join
    res = self._popen.wait(timeout)
  File "/home/kana/yes/envs/detectron2/lib/python3.8/multiprocessing/popen_fork.py", line 47, in wait
    return self.poll(os.WNOHANG if timeout == 0.0 else 0)
  File "/home/kana/yes/envs/detectron2/lib/python3.8/multiprocessing/popen_fork.py", line 27, in poll
    pid, sts = os.waitpid(self.pid, flag)
KeyboardInterrupt